<?xml version="1.0"?>
<robot name="newrobo" xmlns:xacro="http://www.ros.org/wiki/xacro">
	<xacro:include filename="$(find xacro)/define.xacro" />
	<xacro:include filename="$(find shinobi_newrobo_display)/robot/config.xacro" />
	<xacro:include filename="$(find shinobi_newrobo_display)/robot/flipper_macro.xacro" />
	<xacro:include filename="$(find shinobi_newrobo_display)/robot/starWheel_macro.xacro" />

	<link name="arm_base">
		<visual>
			<origin rpy="0 0 0" 
							xyz="0 0 0"/>	
			<geometry>
				<mesh filename="${robotPackagePath}/${modelDataResourseFolder}/arm_base.stl"/>
			</geometry>
		</visual>
	</link>

  <joint name="joint_arm_yaw" type="revolute">
    <axis xyz="0 0 1"/>
    <limit 	lower="${DEG2RAD*armYawAngle_min}" effort="1000.0"  		
						upper="${DEG2RAD*armYawAngle_max}" velocity="0.5"/>
    <origin rpy="0 0 0" 
						xyz="0 0 ${armYawStage_fromBodyTop}"/>
    <parent link="arm_base"/>
    <child link="arm_yaw"/>
  </joint>

	<link name="arm_yaw">
		<visual>
			<origin rpy="0 0 0" 
							xyz="0 0 0"/>
			<geometry>
				<mesh filename="${robotPackagePath}/${modelDataResourseFolder}/arm_yaw.stl"/>
			</geometry>
		</visual>
	</link>
			
  <joint name="joint_arm_pitch" type="revolute">
    <axis xyz="0 1 0"/>
    <limit 	lower="${DEG2RAD*armPitchAngle_min}" effort="1000.0"  		
						upper="${DEG2RAD*armPitchAngle_max}" velocity="0.5"/>
    <origin rpy="0 0 0" 
						xyz="${-armPitchAxis_fromYawAxis} 0 0"/>
    <parent link="arm_yaw"/>
    <child link="arm_pitch"/>
  </joint>

	<link name="arm_pitch">
		<visual>
			<origin rpy="0 0 0" 
							xyz="${-armLinearAxis_fromPitchAxis} 
									0 
									0"/>
			<geometry>
				<mesh filename="${robotPackagePath}/${modelDataResourseFolder}/arm_pitch.stl"/>
			</geometry>
		</visual>
	</link>

</robot>


