<?xml version="1.0"?>
<robot xmlns:xacro="http://www.ros.org/wiki/xacro">
	<xacro:include filename="$(find shinobi_newrobo_display)/robot/config.xacro" />

	<xacro:macro 	name="combine_lr_flippers" 
								params="left_joint_name right_joint_name parent tread suffix *origin">

	<!-- Axis -->
		<joint name="fixedJoint_flipperAxis_${suffix}" type="fixed">
			<insert_block name="origin" />
  	  <parent link="${parent}" />
  	  <child link="virtualLink_flipperAxis_${suffix}"/>
  	</joint>

		<link name="virtualLink_flipperAxis_${suffix}" />

	<!-- left -->
		<joint name="${left_joint_name}" type="revolute">
  	  <axis xyz="0 1 0"/>
			<origin rpy="0 0 0" 
							xyz="0 ${tread/2.0} 0" />
    	<limit 	lower="${DEG2RAD*flipperAngle_min}" effort="1000.0"  		
							upper="${DEG2RAD*flipperAngle_max}" velocity="0.5"/>
  	  <parent link="virtualLink_flipperAxis_${suffix}"/>
  	  <child link="flippper_left_${suffix}"/>
  	</joint>

		<link name="flippper_left_${suffix}">
			<visual>
				<origin rpy="0 0 0" xyz="0 0 0"/>
				<geometry>
					<mesh filename="${robotPackagePath}/newRobotDaes/small_leftFlipper.dae"/>
				</geometry>
			</visual>
		</link>

	<!-- right -->
		<joint name="${right_joint_name}" type="revolute">
  	  <axis xyz="0 1 0"/>
			<origin rpy="0 0 0" 
							xyz="0 ${-tread/2.0} 0" />
    	<limit 	lower="${DEG2RAD*flipperAngle_min}" effort="1000.0"  		
							upper="${DEG2RAD*flipperAngle_max}" velocity="0.5"/>
  	  <parent link="virtualLink_flipperAxis_${suffix}"/>
  	  <child link="flipper_right_${suffix}"/>
  	</joint>

		<link name="flipper_right_${suffix}">
			<visual>
				<origin rpy="0 0 0" xyz="0 0 0"/>
				<geometry>
					<mesh filename="${robotPackagePath}/newRobotDaes/small_rightFlipper.dae"/>
				</geometry>
			</visual>
		</link>

	</xacro:macro>
</robot>









