<?xml version="1.0"?>
<robot name="yozakura" xmlns:xacro="http://www.ros.org/wiki/xacro">
    <xacro:include filename="$(find xacro)/define.xacro"/>
    <xacro:include filename="$(find yozakura_display)/robot/config.xacro"/>
    <xacro:include filename="$(find yozakura_display)/robot/flipper_macro.xacro"/>
    <xacro:include filename="$(find yozakura_display)/robot/wheel_macro.xacro"/>

    <link name="virtual_arm_base">
        <origin rpy="0 0 0" xyz="0 0 0"/>
    </link>

    <joint name="joint_arm_yaw" type="revolute">
        <axis xyz="0 0 1"/>
        <limit lower="${DEG2RAD*armYawAngle_min}" effort="1000.0"
               upper="${DEG2RAD*armYawAngle_max}" velocity="0.5"/>
        <origin rpy="0 0 0"
                xyz="0 0 ${armYawStage_fromBodyTop}"/>
        <parent link="virtual_arm_base"/>
        <child link="arm_yaw"/>
    </joint>

    <link name="arm_yaw">
        <visual>
            <origin rpy="0 0 0"
                    xyz="0 0 0"/>
            <geometry>
                <mesh filename="${robotPackagePath}/${modelDataResourseFolder}/arm_yaw.dae"/>
            </geometry>
        </visual>
    </link>

    <joint name="joint_arm_pitch" type="revolute">
        <axis xyz="0 1 0"/>
        <limit lower="${DEG2RAD*armPitchAngle_min}" effort="1000.0"
               upper="${DEG2RAD*armPitchAngle_max}" velocity="0.5"/>
        <origin rpy="0 0 0"
                xyz="${-armPitchAxis_fromYawAxis} 0 ${armPitchAxis_fromYawStage}"/>
        <parent link="arm_yaw"/>
        <child link="arm_pitch"/>
    </joint>

    <link name="arm_pitch">
        <visual>
            <origin rpy="0 0 0"
                    xyz="${-armLinearAxis_fromPitchAxis} 0 ${-armPitchAxis_fromYawStage + armLinearAxis_fromYawStage}"/>
            <geometry>
                <mesh filename="${robotPackagePath}/${modelDataResourseFolder}/arm_pitch.dae"/>
            </geometry>
        </visual>
    </link>


</robot>























